Workbook

Sheet moras
A1: IDENTIFICACION | B1: SEXO | C1: SALARIO | D1: TIPO_ASEGURAMIENTO | E1: SECTOR | F1: INDICADOR_ACTIVO | G1: INDICADOR.EXTRANJERO | H1: INDICADOR_MOROSO | I1: EDAD | J1: Z-SCORE SALARIO | K1: Valor mayor 1,96 | L1: Z-SCORE EDAD | M1: Valor mayor 1,962 | N1: Imputar con Media para Salario | O1: Imputar con Moda Tipo_aseguramiento | P1: Imputar con Media para Edad
A2: 1 | B2: HOMBRE | D2: ASALARIADO | E2: SECTOR PUBLICO | F2: SI | G2: NO | H2: NO | I2: 42 | J2: =(C2-$S$4)/STDEV($C$2:$C$5001) -> -0.81076736 | K2: =ABS(J2)>1.96 -> FALSE | L2: =(I2-$S$5)/_xlfn.STDEV.S($I$2:$I$5001) -> 0.0066098168 | M2: =ABS(L2)>1.96 -> FALSE | N2: =IF(ISBLANK(C2), $S$4, C2) -> 657534.29 | O2: =IF(D2="", "ASALARIADO", D2) -> ASALARIADO | P2: =IF(ISBLANK(I2), $S$5, I2) -> 42 | R2: Resumen 5 números de columnas numéricas
A3: 2 | B3: HOMBRE | C3: 3315014 | D3: PENSIONADOS EN SU PROPIO SISTEMA | E3: SECTOR PUBLICO | F3: SI | G3: NO | H3: NO | I3: 77 | J3: =(C3-$S$4)/STDEV($C$2:$C$5001) -> 3.276784 | K3: =ABS(J3)>1.96 -> TRUE | L3: =(I3-$S$5)/_xlfn.STDEV.S($I$2:$I$5001) -> 2.4767464 | M3: =ABS(L3)>1.96 -> TRUE | N3: =IF(ISBLANK(C3), $S$4, C3) -> 3315014 | O3: =IF(D3="", "ASALARIADO", D3) -> PENSIONADOS EN SU PROPIO SISTEMA | P3: =IF(ISBLANK(I3), $S$5, I3) -> 77 | S3: Promedio | T3: Máx | U3: Min | V3: Mediana | W3: Cuartil25% | X3: Cuartil75%
A4: 3 | B4: MUJER | C4: 270486.01 | D4: ASALARIADO | E4: SECTOR PRIVADO | F4: SI | G4: NO | H4: NO | I4: 45 | J4: =(C4-$S$4)/STDEV($C$2:$C$5001) -> -0.47724677 | K4: =ABS(J4)>1.96 -> FALSE | L4: =(I4-$S$5)/_xlfn.STDEV.S($I$2:$I$5001) -> 0.21833581 | M4: =ABS(L4)>1.96 -> FALSE | N4: =IF(ISBLANK(C4), $S$4, C4) -> 270486.01 | O4: =IF(D4="", "ASALARIADO", D4) -> ASALARIADO | P4: =IF(ISBLANK(I4), $S$5, I4) -> 45 | R4: Salario | S4: =AVERAGE(C2:C5001) -> 657534.29 | T4: =MAX(C2:C5001) -> 16858742 | U4: =MIN(C2:C5001) -> 10 | V4: =MEDIAN(C2:C5001) -> 408495 | W4: =PERCENTILE(C2:C5001, 0.25) -> 297429 | X4: =PERCENTILE(C2:C5001, 0.75) -> 700000 | AQ4: Opiniones
A5: 4 | B5: MUJER | C5: 544949.83 | D5: ASALARIADO | E5: SECTOR PRIVADO | F5: SI | G5: NO | H5: NO | I5: 49 | J5: =(C5-$S$4)/STDEV($C$2:$C$5001) -> -0.13882136 | K5: =ABS(J5)>1.96 -> FALSE | L5: =(I5-$S$5)/_xlfn.STDEV.S($I$2:$I$5001) -> 0.50063713 | M5: =ABS(L5)>1.96 -> FALSE | N5: =IF(ISBLANK(C5), $S$4, C5) -> 544949.83 | O5: =IF(D5="", "ASALARIADO", D5) -> ASALARIADO | P5: =IF(ISBLANK(I5), $S$5, I5) -> 49 | R5: Edad | S5: =AVERAGE(I2:I5001) -> 41.906344 | T5: =MAX(I2:I5001) -> 99 | U5: =MIN(I2:I5001) -> 14 | V5: =MEDIAN(I2:I5001) -> 40 | W5: =PERCENTILE(I2:I5001, 0.25) -> 31 | X5: =PERCENTILE(I2:I5001, 0.75) -> 52 | AC5: Etiquetas de columna | AH5: Etiquetas de columna | AQ5: Gráfico de sexo: | AR5: Podemos observar que hay una mayor cantidad de hombres que de mujeres, sin embargo, esta cantidad sigue siendo bastante parecida, con 3000 hombres y 2000 mujeres, entonces hay una muestra significativo para ambos sexos.
A6: 5 | B6: MUJER | C6: 210000 | D6: ASALARIADO | E6: SECTOR PRIVADO | F6: SI | G6: NO | H6: NO | I6: 42 | J6: =(C6-$S$4)/STDEV($C$2:$C$5001) -> -0.55182855 | K6: =ABS(J6)>1.96 -> FALSE | L6: =(I6-$S$5)/_xlfn.STDEV.S($I$2:$I$5001) -> 0.0066098168 | M6: =ABS(L6)>1.96 -> FALSE | N6: =IF(ISBLANK(C6), $S$4, C6) -> 210000 | O6: =IF(D6="", "ASALARIADO", D6) -> ASALARIADO | P6: =IF(ISBLANK(I6), $S$5, I6) -> 42 | AC6: HOMBRE | AD6: MUJER | AE6: Total general | AH6: ASALARIADO | AI6: ASEGURADO VOLUNTARIO | AJ6: CONVENIOS ESPECIALES DE ASEGURADOS VOLUNTARIOS | AK6: CONVENIOS ESPECIALES DE TRABAJADORES INDEPENDIENTES | AL6: PENSIONADOS EN SU PROPIO SISTEMA | AM6: TRABAJADOR INDEPENDIENTE | AN6: Total general | AQ6: Gráfico de tipo de aseguramiento: | AR6: Se puede analizar que la mayor cantidad de asegurados que hay es por asalariado y la que menos hay es de convenios especiales de asegurados voluntarios, esto muestra que la gran mayoría de personas que cuentan con un seguro es porque estos trabajan y al percibir un salario los empleadores se ven obligados a dar un seguro a sus empleados.
A7: 6 | B7: HOMBRE | C7: 397150 | D7: ASALARIADO | E7: SECTOR PRIVADO | F7: SI | G7: NO | H7: NO | I7: 44 | J7: =(C7-$S$4)/STDEV($C$2:$C$5001) -> -0.32106475 | K7: =ABS(J7)>1.96 -> FALSE | L7: =(I7-$S$5)/_xlfn.STDEV.S($I$2:$I$5001) -> 0.14776048 | M7: =ABS(L7)>1.96 -> FALSE | N7: =IF(ISBLANK(C7), $S$4, C7) -> 397150 | O7: =IF(D7="", "ASALARIADO", D7) -> ASALARIADO | P7: =IF(ISBLANK(I7), $S$5, I7) -> 44 | R7: Valores faltantes en cada columna | AB7: Cuenta de SEXO | AC7: 3012 | AD7: 1988 | AE7: 5000 | AG7: Cuenta de Imputar con Moda Tipo_aseguramiento | AH7: 3464 | AI7: 436 | AJ7: 31 | AK7: 157 | AL7: 212 | AM7: 700 | AN7: 5000 | AQ7: Gráfico de sector: | AR7: Se observa que la gran cantidad de personas estan en el sector privado, mientras que un leve porcentaje se encuentra en sector público.
A8: 7 | B8: HOMBRE | C8: 854712 | D8: ASALARIADO | E8: SECTOR PRIVADO | F8: SI | G8: NO | H8: NO | I8: 38 | J8: =(C8-$S$4)/STDEV($C$2:$C$5001) -> 0.24312838 | K8: =ABS(J8)>1.96 -> FALSE | L8: =(I8-$S$5)/_xlfn.STDEV.S($I$2:$I$5001) -> -0.2756915 | M8: =ABS(L8)>1.96 -> FALSE | N8: =IF(ISBLANK(C8), $S$4, C8) -> 854712 | O8: =IF(D8="", "ASALARIADO", D8) -> ASALARIADO | P8: =IF(ISBLANK(I8), $S$5, I8) -> 38 | R8: Identificación | S8: Sexo | T8: Salario | U8: Tipo_aseguramiento | V8: Sector | W8: Indicador_activo | X8: Indicador.extranjero | Y8: Indicadro_moroso | Z8: Edad | AQ8: Gráfico de indicador activo: | AR8: En el gráfico analizamos que para la gran mayoría su seguro si está activo, mientras que un muy pequeño porcentaje no lo tiene activo, lo cual hace sentido pues a todas las personas aseguradas sirve tener su seguro activo en caso de alguna emergencia que sea necesario hacer uso del seguro.
A9: 8 | B9: HOMBRE | C9: 401000 | D9: ASALARIADO | E9: SECTOR PRIVADO | F9: SI | G9: SI | H9: SI | I9: 36 | J9: =(C9-$S$4)/STDEV($C$2:$C$5001) -> -0.31631754 | K9: =ABS(J9)>1.96 -> FALSE | L9: =(I9-$S$5)/_xlfn.STDEV.S($I$2:$I$5001) -> -0.41684216 | M9: =ABS(L9)>1.96 -> FALSE | N9: =IF(ISBLANK(C9), $S$4, C9) -> 401000 | O9: =IF(D9="", "ASALARIADO", D9) -> ASALARIADO | P9: =IF(ISBLANK(I9), $S$5, I9) -> 36 | R9: =COUNTBLANK(A2:A5001)/5000 -> 0 | S9: =COUNTBLANK(B2:B5001)/5000 -> 0 | T9: =COUNTBLANK(C2:C5001)/5000 -> 0.0006 | U9: =COUNTBLANK(D2:D5001)/5000 -> 0.0004 | V9: =COUNTBLANK(E2:E5001)/5000 -> 0 | W9: =COUNTBLANK(F2:F5001)/5000 -> 0 | X9: =COUNTBLANK(G2:G5001)/5000 -> 0 | Y9: =COUNTBLANK(H2:H5001)/5000 -> 0 | Z9: =COUNTBLANK(I2:I5001)/5000 -> 0.0006 | AQ9: Gráfico de indicador extranjero: | AR9: La mayoría son personas nacionales, sin embargo sigue existiendo un pequeño porcentaje que es extranjero, por lo que es importante tomar esta población en cuenta.
A10: 9 | B10: MUJER | C10: 264703.96 | D10: ASALARIADO | E10: SECTOR PRIVADO | F10: SI | G10: NO | H10: NO | I10: 21 | J10: =(C10-$S$4)/STDEV($C$2:$C$5001) -> -0.48437628 | K10: =ABS(J10)>1.96 -> FALSE | L10: =(I10-$S$5)/_xlfn.STDEV.S($I$2:$I$5001) -> -1.4754721 | M10: =ABS(L10)>1.96 -> FALSE | N10: =IF(ISBLANK(C10), $S$4, C10) -> 264703.96 | O10: =IF(D10="", "ASALARIADO", D10) -> ASALARIADO | P10: =IF(ISBLANK(I10), $S$5, I10) -> 21 | AQ10: Gráfico de indicador moroso: | AR10: La mayoría son personas no morosas, sim embargo si hay un porcentaje importante que es moroso de un 17,4%, por lo que es importante analizar por qué estas personas no están pagando el seguro.
A11: 10 | B11: HOMBRE | C11: 4677126.8 | D11: ASALARIADO | E11: SECTOR PRIVADO | F11: SI | G11: NO | H11: NO | I11: 40 | J11: =(C11-$S$4)/STDEV($C$2:$C$5001) -> 4.9563262 | K11: =ABS(J11)>1.96 -> TRUE | L11: =(I11-$S$5)/_xlfn.STDEV.S($I$2:$I$5001) -> -0.13454084 | M11: =ABS(L11)>1.96 -> FALSE | N11: =IF(ISBLANK(C11), $S$4, C11) -> 4677126.8 | O11: =IF(D11="", "ASALARIADO", D11) -> ASALARIADO | P11: =IF(ISBLANK(I11), $S$5, I11) -> 40
A12: 11 | B12: MUJER | C12: 1200000 | D12: ASALARIADO | E12: SECTOR PRIVADO | F12: SI | G12: NO | H12: NO | I12: 30 | J12: =(C12-$S$4)/STDEV($C$2:$C$5001) -> 0.66888297 | K12: =ABS(J12)>1.96 -> FALSE | L12: =(I12-$S$5)/_xlfn.STDEV.S($I$2:$I$5001) -> -0.84029414 | M12: =ABS(L12)>1.96 -> FALSE | N12: =IF(ISBLANK(C12), $S$4, C12) -> 1200000 | O12: =IF(D12="", "ASALARIADO", D12) -> ASALARIADO | P12: =IF(ISBLANK(I12), $S$5, I12) -> 30 | R12: Tipo de aseguramiento | S12: Frecuencia
A13: 12 | B13: MUJER | C13: 1030132 | D13: ASALARIADO | E13: SECTOR PUBLICO | F13: SI | G13: NO | H13: SI | I13: 58 | J13: =(C13-$S$4)/STDEV($C$2:$C$5001) -> 0.4594286 | K13: =ABS(J13)>1.96 -> FALSE | L13: =(I13-$S$5)/_xlfn.STDEV.S($I$2:$I$5001) -> 1.1358151 | M13: =ABS(L13)>1.96 -> FALSE | N13: =IF(ISBLANK(C13), $S$4, C13) -> 1030132 | O13: =IF(D13="", "ASALARIADO", D13) -> ASALARIADO | P13: =IF(ISBLANK(I13), $S$5, I13) -> 58 | R13: Asalariado | S13: =COUNTIF(D2:D5001, "ASALARIADO") -> 3462
A14: 13 | B14: HOMBRE | C14: 731287.5 | D14: ASALARIADO | E14: SECTOR PUBLICO | F14: SI | G14: NO | H14: NO | I14: 40 | J14: =(C14-$S$4)/STDEV($C$2:$C$5001) -> 0.090940799 | K14: =ABS(J14)>1.96 -> FALSE | L14: =(I14-$S$5)/_xlfn.STDEV.S($I$2:$I$5001) -> -0.13454084 | M14: =ABS(L14)>1.96 -> FALSE | N14: =IF(ISBLANK(C14), $S$4, C14) -> 731287.5 | O14: =IF(D14="", "ASALARIADO", D14) -> ASALARIADO | P14: =IF(ISBLANK(I14), $S$5, I14) -> 40 | R14: Asegurado voluntario | S14: =COUNTIF(D2:D5001, "ASEGURADO VOLUNTARIO") -> 436
A15: 14 | B15: HOMBRE | C15: 282305 | D15: ASEGURADO VOLUNTARIO | E15: SECTOR PRIVADO | F15: SI | G15: NO | H15: NO | I15: 51 | J15: =(C15-$S$4)/STDEV($C$2:$C$5001) -> -0.46267346 | K15: =ABS(J15)>1.96 -> FALSE | L15: =(I15-$S$5)/_xlfn.STDEV.S($I$2:$I$5001) -> 0.64178779 | M15: =ABS(L15)>1.96 -> FALSE | N15: =IF(ISBLANK(C15), $S$4, C15) -> 282305 | O15: =IF(D15="", "ASALARIADO", D15) -> ASEGURADO VOLUNTARIO | P15: =IF(ISBLANK(I15), $S$5, I15) -> 51 | R15: Convenios especiales de asegurados voluntarios | S15: =COUNTIF(D2:D5001, "CONVENIOS ESPECIALES DE ASEGURADOS VOLUNTARIOS") -> 31
A16: 15 | B16: MUJER | C16: 343390.86 | D16: TRABAJADOR INDEPENDIENTE | E16: SECTOR PRIVADO | F16: SI | G16: NO | H16: NO | I16: 59 | J16: =(C16-$S$4)/STDEV($C$2:$C$5001) -> -0.38735203 | K16: =ABS(J16)>1.96 -> FALSE | L16: =(I16-$S$5)/_xlfn.STDEV.S($I$2:$I$5001) -> 1.2063904 | M16: =ABS(L16)>1.96 -> FALSE | N16: =IF(ISBLANK(C16), $S$4, C16) -> 343390.86 | O16: =IF(D16="", "ASALARIADO", D16) -> TRABAJADOR INDEPENDIENTE | P16: =IF(ISBLANK(I16), $S$5, I16) -> 59 | R16: Convenios especiales de trabajadores independientes | S16: =COUNTIF(D2:D5001, "CONVENIOS ESPECIALES DE TRABAJADORES INDEPENDIENTES") -> 157
A17: 16 | B17: MUJER | C17: 1943489.5 | D17: ASALARIADO | E17: SECTOR PUBLICO | F17: SI | G17: NO | H17: NO | I17: 58 | J17: =(C17-$S$4)/STDEV($C$2:$C$5001) -> 1.5856367 | K17: =ABS(J17)>1.96 -> FALSE | L17: =(I17-$S$5)/_xlfn.STDEV.S($I$2:$I$5001) -> 1.1358151 | M17: =ABS(L17)>1.96 -> FALSE | N17: =IF(ISBLANK(C17), $S$4, C17) -> 1943489.5 | O17: =IF(D17="", "ASALARIADO", D17) -> ASALARIADO | P17: =IF(ISBLANK(I17), $S$5, I17) -> 58 | R17: Pensionados en su propio sistema | S17: =COUNTIF(D2:D5001, "PENSIONADOS EN SU PROPIO SISTEMA") -> 212
A18: 17 | B18: MUJER | C18: 1108980 | D18: ASALARIADO | E18: SECTOR PUBLICO | F18: SI | G18: NO | H18: SI | I18: 36 | J18: =(C18-$S$4)/STDEV($C$2:$C$5001) -> 0.55665149 | K18: =ABS(J18)>1.96 -> FALSE | L18: =(I18-$S$5)/_xlfn.STDEV.S($I$2:$I$5001) -> -0.41684216 | M18: =ABS(L18)>1.96 -> FALSE | N18: =IF(ISBLANK(C18), $S$4, C18) -> 1108980 | O18: =IF(D18="", "ASALARIADO", D18) -> ASALARIADO | P18: =IF(ISBLANK(I18), $S$5, I18) -> 36 | R18: Trabajador independiente | S18: =COUNTIF(D2:D5001, "TRABAJADOR INDEPENDIENTE") -> 700
A19: 18 | B19: MUJER | C19: 133157 | D19: ASALARIADO | E19: SECTOR PRIVADO | F19: SI | G19: NO | H19: NO | I19: 39 | J19: =(C19-$S$4)/STDEV($C$2:$C$5001) -> -0.6465792 | K19: =ABS(J19)>1.96 -> FALSE | L19: =(I19-$S$5)/_xlfn.STDEV.S($I$2:$I$5001) -> -0.20511617 | M19: =ABS(L19)>1.96 -> FALSE | N19: =IF(ISBLANK(C19), $S$4, C19) -> 133157 | O19: =IF(D19="", "ASALARIADO", D19) -> ASALARIADO | P19: =IF(ISBLANK(I19), $S$5, I19) -> 39
A20: 19 | B20: HOMBRE | C20: 553939 | D20: ASALARIADO | E20: SECTOR PRIVADO | F20: SI | G20: NO | H20: NO | I20: 45 | J20: =(C20-$S$4)/STDEV($C$2:$C$5001) -> -0.12773734 | K20: =ABS(J20)>1.96 -> FALSE | L20: =(I20-$S$5)/_xlfn.STDEV.S($I$2:$I$5001) -> 0.21833581 | M20: =ABS(L20)>1.96 -> FALSE | N20: =IF(ISBLANK(C20), $S$4, C20) -> 553939 | O20: =IF(D20="", "ASALARIADO", D20) -> ASALARIADO | P20: =IF(ISBLANK(I20), $S$5, I20) -> 45
A21: 20 | B21: MUJER | C21: 309820 | D21: ASEGURADO VOLUNTARIO | E21: SECTOR PRIVADO | F21: SI | G21: SI | H21: SI | I21: 52 | J21: =(C21-$S$4)/STDEV($C$2:$C$5001) -> -0.42874631 | K21: =ABS(J21)>1.96 -> FALSE | L21: =(I21-$S$5)/_xlfn.STDEV.S($I$2:$I$5001) -> 0.71236312 | M21: =ABS(L21)>1.96 -> FALSE | N21: =IF(ISBLANK(C21), $S$4, C21) -> 309820 | O21: =IF(D21="", "ASALARIADO", D21) -> ASEGURADO VOLUNTARIO | P21: =IF(ISBLANK(I21), $S$5, I21) -> 52
A22: 21 | B22: MUJER | D22: ASALARIADO | E22: SECTOR PRIVADO | F22: SI | G22: SI | H22: NO | I22: 28 | J22: =(C22-$S$4)/STDEV($C$2:$C$5001) -> -0.81076736 | K22: =ABS(J22)>1.96 -> FALSE | L22: =(I22-$S$5)/_xlfn.STDEV.S($I$2:$I$5001) -> -0.9814448 | M22: =ABS(L22)>1.96 -> FALSE | N22: =IF(ISBLANK(C22), $S$4, C22) -> 657534.29 | O22: =IF(D22="", "ASALARIADO", D22) -> ASALARIADO | P22: =IF(ISBLANK(I22), $S$5, I22) -> 28
A23: 22 | B23: HOMBRE | C23: 278030 | D23: CONVENIOS ESPECIALES DE TRABAJADORES INDEPENDIENTES | E23: SECTOR PRIVADO | F23: SI | G23: NO | H23: NO | I23: 59 | J23: =(C23-$S$4)/STDEV($C$2:$C$5001) -> -0.46794471 | K23: =ABS(J23)>1.96 -> FALSE | L23: =(I23-$S$5)/_xlfn.STDEV.S($I$2:$I$5001) -> 1.2063904 | M23: =ABS(L23)>1.96 -> FALSE | N23: =IF(ISBLANK(C23), $S$4, C23) -> 278030 | O23: =IF(D23="", "ASALARIADO", D23) -> CONVENIOS ESPECIALES DE TRABAJADORES INDEPENDIENTES | P23: =IF(ISBLANK(I23), $S$5, I23) -> 59
A24: 23 | B24: HOMBRE | C24: 2124814 | D24: ASALARIADO | E24: SECTOR PRIVADO | F24: SI | G24: NO | H24: NO | I24: 32 | J24: =(C24-$S$4)/STDEV($C$2:$C$5001) -> 1.8092174 | K24: =ABS(J24)>1.96 -> FALSE | L24: =(I24-$S$5)/_xlfn.STDEV.S($I$2:$I$5001) -> -0.69914348 | M24: =ABS(L24)>1.96 -> FALSE | N24: =IF(ISBLANK(C24), $S$4, C24) -> 2124814 | O24: =IF(D24="", "ASALARIADO", D24) -> ASALARIADO | P24: =IF(ISBLANK(I24), $S$5, I24) -> 32
A25: 24 | B25: HOMBRE | C25: 191744.68 | D25: ASALARIADO | E25: SECTOR PRIVADO | F25: SI | G25: NO | H25: NO | I25: 18 | J25: =(C25-$S$4)/STDEV($C$2:$C$5001) -> -0.57433813 | K25: =ABS(J25)>1.96 -> FALSE | L25: =(I25-$S$5)/_xlfn.STDEV.S($I$2:$I$5001) -> -1.6871981 | M25: =ABS(L25)>1.96 -> FALSE | N25: =IF(ISBLANK(C25), $S$4, C25) -> 191744.68 | O25: =IF(D25="", "ASALARIADO", D25) -> ASALARIADO | P25: =IF(ISBLANK(I25), $S$5, I25) -> 18 | AC25: Etiquetas de columna | AH25: Etiquetas de columna | AM25: Etiquetas de columna
A26: 25 | B26: MUJER | C26: 1117489 | D26: ASALARIADO | E26: SECTOR PUBLICO | F26: SI | G26: NO | H26: SI | I26: 36 | J26: =(C26-$S$4)/STDEV($C$2:$C$5001) -> 0.56714345 | K26: =ABS(J26)>1.96 -> FALSE | L26: =(I26-$S$5)/_xlfn.STDEV.S($I$2:$I$5001) -> -0.41684216 | M26: =ABS(L26)>1.96 -> FALSE | N26: =IF(ISBLANK(C26), $S$4, C26) -> 1117489 | O26: =IF(D26="", "ASALARIADO", D26) -> ASALARIADO | P26: =IF(ISBLANK(I26), $S$5, I26) -> 36 | AC26: SECTOR PRIVADO | AD26: SECTOR PUBLICO | AE26: Total general | AH26: NO | AI26: SI | AJ26: Total general | AM26: NO | AN26: SI | AO26: Total general
A27: 26 | B27: HOMBRE | C27: 1451530 | D27: PENSIONADOS EN SU PROPIO SISTEMA | E27: SECTOR PUBLICO | F27: SI | G27: NO | H27: NO | I27: 62 | J27: =(C27-$S$4)/STDEV($C$2:$C$5001) -> 0.97903001 | K27: =ABS(J27)>1.96 -> FALSE | L27: =(I27-$S$5)/_xlfn.STDEV.S($I$2:$I$5001) -> 1.4181164 | M27: =ABS(L27)>1.96 -> FALSE | N27: =IF(ISBLANK(C27), $S$4, C27) -> 1451530 | O27: =IF(D27="", "ASALARIADO", D27) -> PENSIONADOS EN SU PROPIO SISTEMA | P27: =IF(ISBLANK(I27), $S$5, I27) -> 62 | AB27: Cuenta de SECTOR | AC27: 3906 | AD27: 1094 | AE27: 5000 | AG27: Cuenta de INDICADOR_ACTIVO | AH27: 34 | AI27: 4966 | AJ27: 5000 | AL27: Cuenta de INDICADOR.EXTRANJERO | AM27: 4397 | AN27: 603 | AO27: 5000
A28: 27 | B28: HOMBRE | C28: 66700 | D28: ASALARIADO | E28: SECTOR PRIVADO | F28: SI | G28: NO | H28: NO | I28: 38 | J28: =(C28-$S$4)/STDEV($C$2:$C$5001) -> -0.72852347 | K28: =ABS(J28)>1.96 -> FALSE | L28: =(I28-$S$5)/_xlfn.STDEV.S($I$2:$I$5001) -> -0.2756915 | M28: =ABS(L28)>1.96 -> FALSE | N28: =IF(ISBLANK(C28), $S$4, C28) -> 66700 | O28: =IF(D28="", "ASALARIADO", D28) -> ASALARIADO | P28: =IF(ISBLANK(I28), $S$5, I28) -> 38
A29: 28 | B29: MUJER | C29: 73410 | D29: ASALARIADO | E29: SECTOR PRIVADO | F29: SI | G29: SI | H29: NO | I29: 22 | J29: =(C29-$S$4)/STDEV($C$2:$C$5001) -> -0.72024975 | K29: =ABS(J29)>1.96 -> FALSE | L29: =(I29-$S$5)/_xlfn.STDEV.S($I$2:$I$5001) -> -1.4048968 | M29: =ABS(L29)>1.96 -> FALSE | N29: =IF(ISBLANK(C29), $S$4, C29) -> 73410 | O29: =IF(D29="", "ASALARIADO", D29) -> ASALARIADO | P29: =IF(ISBLANK(I29), $S$5, I29) -> 22
A30: 29 | B30: HOMBRE | C30: 815355.66 | D30: ASALARIADO | E30: SECTOR PUBLICO | F30: SI | G30: NO | H30: NO | I30: 42 | J30: =(C30-$S$4)/STDEV($C$2:$C$5001) -> 0.19460037 | K30: =ABS(J30)>1.96 -> FALSE | L30: =(I30-$S$5)/_xlfn.STDEV.S($I$2:$I$5001) -> 0.0066098168 | M30: =ABS(L30)>1.96 -> FALSE | N30: =IF(ISBLANK(C30), $S$4, C30) -> 815355.66 | O30: =IF(D30="", "ASALARIADO", D30) -> ASALARIADO | P30: =IF(ISBLANK(I30), $S$5, I30) -> 42
A31: 30 | B31: HOMBRE | C31: 398125 | D31: ASALARIADO | E31: SECTOR PRIVADO | F31: SI | G31: NO | H31: NO | I31: 38 | J31: =(C31-$S$4)/STDEV($C$2:$C$5001) -> -0.31986254 | K31: =ABS(J31)>1.96 -> FALSE | L31: =(I31-$S$5)/_xlfn.STDEV.S($I$2:$I$5001) -> -0.2756915 | M31: =ABS(L31)>1.96 -> FALSE | N31: =IF(ISBLANK(C31), $S$4, C31) -> 398125 | O31: =IF(D31="", "ASALARIADO", D31) -> ASALARIADO | P31: =IF(ISBLANK(I31), $S$5, I31) -> 38
A32: 31 | B32: HOMBRE | C32: 606763.96 | D32: ASALARIADO | E32: SECTOR PRIVADO | F32: SI | G32: NO | H32: NO | I32: 39 | J32: =(C32-$S$4)/STDEV($C$2:$C$5001) -> -0.062601949 | K32: =ABS(J32)>1.96 -> FALSE | L32: =(I32-$S$5)/_xlfn.STDEV.S($I$2:$I$5001) -> -0.20511617 | M32: =ABS(L32)>1.96 -> FALSE | N32: =IF(ISBLANK(C32), $S$4, C32) -> 606763.96 | O32: =IF(D32="", "ASALARIADO", D32) -> ASALARIADO | P32: =IF(ISBLANK(I32), $S$5, I32) -> 39
A33: 32 | B33: HOMBRE | C33: 360420 | D33: TRABAJADOR INDEPENDIENTE | E33: SECTOR PRIVADO | F33: SI | G33: NO | H33: SI | I33: 53 | J33: =(C33-$S$4)/STDEV($C$2:$C$5001) -> -0.36635439 | K33: =ABS(J33)>1.96 -> FALSE | L33: =(I33-$S$5)/_xlfn.STDEV.S($I$2:$I$5001) -> 0.78293845 | M33: =ABS(L33)>1.96 -> FALSE | N33: =IF(ISBLANK(C33), $S$4, C33) -> 360420 | O33: =IF(D33="", "ASALARIADO", D33) -> TRABAJADOR INDEPENDIENTE | P33: =IF(ISBLANK(I33), $S$5, I33) -> 53
A34: 33 | B34: MUJER | C34: 297046 | D34: ASALARIADO | E34: SECTOR PRIVADO | F34: SI | G34: SI | H34: NO | I34: 41 | J34: =(C34-$S$4)/STDEV($C$2:$C$5001) -> -0.44449719 | K34: =ABS(J34)>1.96 -> FALSE | L34: =(I34-$S$5)/_xlfn.STDEV.S($I$2:$I$5001) -> -0.063965513 | M34: =ABS(L34)>1.96 -> FALSE | N34: =IF(ISBLANK(C34), $S$4, C34) -> 297046 | O34: =IF(D34="", "ASALARIADO", D34) -> ASALARIADO | P34: =IF(ISBLANK(I34), $S$5, I34) -> 41
A35: 34 | B35: HOMBRE | C35: 558030 | D35: ASALARIADO | E35: SECTOR PRIVADO | F35: SI | G35: NO | H35: NO | I35: 28 | J35: =(C35-$S$4)/STDEV($C$2:$C$5001) -> -0.12269297 | K35: =ABS(J35)>1.96 -> FALSE | L35: =(I35-$S$5)/_xlfn.STDEV.S($I$2:$I$5001) -> -0.9814448 | M35: =ABS(L35)>1.96 -> FALSE | N35: =IF(ISBLANK(C35), $S$4, C35) -> 558030 | O35: =IF(D35="", "ASALARIADO", D35) -> ASALARIADO | P35: =IF(ISBLANK(I35), $S$5, I35) -> 28
A36: 35 | B36: HOMBRE | C36: 68309.03 | D36: ASALARIADO | E36: SECTOR PRIVADO | F36: SI | G36: NO | H36: NO | I36: 43 | J36: =(C36-$S$4)/STDEV($C$2:$C$5001) -> -0.72653946 | K36: =ABS(J36)>1.96 -> FALSE | L36: =(I36-$S$5)/_xlfn.STDEV.S($I$2:$I$5001) -> 0.077185147 | M36: =ABS(L36)>1.96 -> FALSE | N36: =IF(ISBLANK(C36), $S$4, C36) -> 68309.03 | O36: =IF(D36="", "ASALARIADO", D36) -> ASALARIADO | P36: =IF(ISBLANK(I36), $S$5, I36) -> 43
A37: 36 | B37: HOMBRE | D37: ASALARIADO | E37: SECTOR PUBLICO | F37: SI | G37: NO | H37: NO | I37: 62 | J37: =(C37-$S$4)/STDEV($C$2:$C$5001) -> -0.81076736 | K37: =ABS(J37)>1.96 -> FALSE | L37: =(I37-$S$5)/_xlfn.STDEV.S($I$2:$I$5001) -> 1.4181164 | M37: =ABS(L37)>1.96 -> FALSE | N37: =IF(ISBLANK(C37), $S$4, C37) -> 657534.29 | O37: =IF(D37="", "ASALARIADO", D37) -> ASALARIADO | P37: =IF(ISBLANK(I37), $S$5, I37) -> 62
A38: 37 | B38: HOMBRE | C38: 1552307.5 | D38: ASALARIADO | E38: SECTOR PRIVADO | F38: SI | G38: SI | H38: NO | I38: 41 | J38: =(C38-$S$4)/STDEV($C$2:$C$5001) -> 1.1032929 | K38: =ABS(J38)>1.96 -> FALSE | L38: =(I38-$S$5)/_xlfn.STDEV.S($I$2:$I$5001) -> -0.063965513 | M38: =ABS(L38)>1.96 -> FALSE | N38: =IF(ISBLANK(C38), $S$4, C38) -> 1552307.5 | O38: =IF(D38="", "ASALARIADO", D38) -> ASALARIADO | P38: =IF(ISBLANK(I38), $S$5, I38) -> 41
A39: 38 | B39: HOMBRE | C39: 1531575 | D39: ASEGURADO VOLUNTARIO | E39: SECTOR PRIVADO | F39: SI | G39: SI | H39: NO | I39: 66 | J39: =(C39-$S$4)/STDEV($C$2:$C$5001) -> 1.0777289 | K39: =ABS(J39)>1.96 -> FALSE | L39: =(I39-$S$5)/_xlfn.STDEV.S($I$2:$I$5001) -> 1.7004177 | M39: =ABS(L39)>1.96 -> FALSE | N39: =IF(ISBLANK(C39), $S$4, C39) -> 1531575 | O39: =IF(D39="", "ASALARIADO", D39) -> ASEGURADO VOLUNTARIO | P39: =IF(ISBLANK(I39), $S$5, I39) -> 66
A40: 39 | B40: HOMBRE | C40: 3220569.1 | D40: ASALARIADO | E40: SECTOR PRIVADO | F40: SI | G40: NO | H40: NO | I40: 48 | J40: =(C40-$S$4)/STDEV($C$2:$C$5001) -> 3.1603294 | K40: =ABS(J40)>1.96 -> TRUE | L40: =(I40-$S$5)/_xlfn.STDEV.S($I$2:$I$5001) -> 0.4300618 | M40: =ABS(L40)>1.96 -> FALSE | N40: =IF(ISBLANK(C40), $S$4, C40) -> 3220569.1 | O40: =IF(D40="", "ASALARIADO", D40) -> ASALARIADO | P40: =IF(ISBLANK(I40), $S$5, I40) -> 48
...

Sheet Gráficos morosidad categóricas
A1: SEXO | B1: % DE MOROSOSO
A2: Hombre | B2: =COUNTIFS(moras!B2:B5001, "HOMBRE", moras!H2:H5001, "SI")/COUNTIF(moras!B2:B5001, "HOMBRE") -> 0.17729084 | E2: Etiquetas de columna | J2: Etiquetas de columna | O2: Etiquetas de columna | S2: Opiniones:
A3: Mujer | B3: =COUNTIFS(moras!B2:B5001, "MUJER", moras!H2:H5001, "SI")/COUNTIF(moras!B2:B5001, "MUJER") -> 0.16901408 | E3: Hombre | F3: Mujer | G3: Total general | J3: Privado | K3: Público | L3: Total general | O3: No | P3: Si | Q3: Total general | S3: Gráfico comparación sexo con morosidad: | T3: Se puede observar que los hombres son mas morosos que las mujeres, sin embargo esta diferencia es de menos de 1%, por lo que ambos son casi igual de morosos, por lo que podemos inducir que no existe un sesgo entre sexos.
A4: SECTOR | B4: % DE MOROSOSO | D4: Suma de % DE MOROSOSO | E4: 0.17729084 | F4: 0.16901408 | G4: 0.34630492 | I4: Suma de % DE MOROSOSO | J4: 0.18023554 | K4: 0.15173675 | L4: 0.33197228 | N4: Suma de % DE MOROSOSO | O4: 0.52941176 | P4: 0.17156665 | Q4: 0.70097842 | S4: Gráfico comparación sector con morosidad: | T4: En el gráficico se puede observar que la mayor cantidad de personas morosas se encuentran en el sector privado, pues hay una diferencia de un poco más de 3%, por lo que hay un pequeño sesgo entre el sector privado y el sector público, pero no es tan grande, de igual forma el sector privado es mucho menos abundante que el sector público, por lo que proporcionalmente hay muchas personas morosas dentro del sector privado, por lo que se podría poner más atención en los por qué de este.
A5: Público | B5: =COUNTIFS(moras!E2:E5001,"SECTOR PUBLICO", moras!H2:H5001, "SI")/COUNTIF(moras!E2:E5001,"SECTOR PUBLICO") -> 0.15173675 | S5: Gráfico comparación tipo de aseguramiento con morosidad: | T5: Se puede analizar desde el gráfico que las personas trbajadoras independientes son más morosas que todos los otros tipos de aseguramiento, esto se puede deber a que los trabajadores independientes son una población que su ingreso no es estable y varia depende de la cantidad de trabajo que consiguieron, por lo que hacer pagos periodicos de un seguro se puede complicar. También es importante observar que los asegurados voluntarios y los asalariados tienen mas de un 10% de personas morosas, respecto a los asegurados voluntarios una de sus razones puede ser que al existir una autogestión del pago de este se les puede olvidar o no saber como hacer bien el proceso.También observe que los que tienen menos porcentaje o nulo se puede deber a que estos están mayor regulados por el estado o que sus planes de pensión lo hacen automáticamente como parte de los beneficios que hacerlo por cuenta propia con un banco puede dar.
A6: Privado | B6: =COUNTIFS(moras!E2:E5001,"SECTOR PRIVADO", moras!H2:H5001, "SI")/COUNTIF(moras!E2:E5001,"SECTOR PRIVADO") -> 0.18023554 | S6: Gráfico comparación indicador activo con morosidad: | T6: En el gráfico se ve que las personas que no tienen su seguro activo son mucho más morosos con casi 53%, lo que hace sentido, pues al no tenerlo activo se puede deber a muchas razones, pero una de estas puede ser el no tener el pago al día. De igual forma hay un 17,16% de personas con el seguro activo que son morosas, por lo que también se puede indagar en las diferentes razones a las que se debe esto. La diferencia tan grande que hay entre estas hace pensar que esta directamente relacionado con la morosidad.
A7: TIPO ASEGURAMIENTO | B7: % DE MOROSOSO | S7: Gráfico comparación indicador extranjero con morosidad: | T7: Se analiza del gráfico que las personas extranjeras son más morosas pues estas personas normalmente tiene oportunidades de trabajmos menos formales y debido a la inestabilidad migratoria pueden ser mas suceptibles a ser morosos, también el constante cambio de empleo o residencia que se ve directamente relacionado con lo último dicho afecta. Aunqe las personas nacionales también cuentan con un porcentaje superior a los 15 puntos porcentuales, por lo cual se puede deber a diferentes razones que se pudieron observar en otros gráficos.
A8: Asalariado | B8: =COUNTIFS(moras!O2:O5001,"ASALARIADO", moras!H2:H5001, "SI")/COUNTIF(moras!O2:O5001,"ASALARIADO") -> 0.1198037
A9: Asegurado voluntario | B9: =COUNTIFS(moras!O2:O5001,"ASEGURADO VOLUNTARIO", moras!H2:H5001, "SI")/COUNTIF(moras!O2:O5001,"ASEGURADO VOLUNTARIO") -> 0.13302752
A10: Convenios especiales de asegurados voluntarios | B10: =COUNTIFS(moras!O2:O5001,"CONVENIOS ESPECIALES DE ASEGURADOS VOLUNTARIOS", moras!H2:H5001, "SI")/COUNTIF(moras!O2:O5001,"CONVENIOS ESPECIALES DE ASEGURADOS VOLUNTARIOS") -> 0
A11: Convenios especiales de trabajadores independientes | B11: =COUNTIFS(moras!O2:O5001,"CONVENIOS ESPECIALES DE TRABAJADORES INDEPENDIENTES", moras!H2:H5001, "SI")/COUNTIF(moras!O2:O5001,"CONVENIOS ESPECIALES DE TRABAJADORES INDEPENDIENTES") -> 0.025477707
A12: Pensionados en su propio sistema | B12: =COUNTIFS(moras!O2:O5001,"PENSIONADOS EN SU PROPIO SISTEMA", moras!H2:H5001, "SI")/COUNTIF(moras!O2:O5001,"PENSIONADOS EN SU PROPIO SISTEMA") -> 0
A13: Trabajador independiente | B13: =COUNTIFS(moras!D2:D5001,"TRABAJADOR INDEPENDIENTE", moras!H2:H5001, "SI")/COUNTIF(moras!D2:D5001,"TRABAJADOR INDEPENDIENTE") -> 0.56142857
A14: INDICADOR ACTIVO | B14: % DE MOROSOSO
A15: Si | B15: =COUNTIFS(moras!F2:F5001, "SI", moras!H2:H5001, "SI")/COUNTIF(moras!F2:F5001, "SI") -> 0.17156665
A16: No | B16: =COUNTIFS(moras!F2:F5001, "NO", moras!H2:H5001, "SI")/COUNTIF(moras!F2:F5001, "NO") -> 0.52941176
A17: INDICADOR EXTRANJERO | B17: % DE MOROSOSO
A18: Si | B18: =COUNTIFS(moras!G2:G5001, "SI", moras!H2:H5001, "SI")/COUNTIF(moras!G2:G5001, "SI") -> 0.24046434
A19: No | B19: =COUNTIFS(moras!G2:G5001, "NO", moras!H2:H5001, "SI")/COUNTIF(moras!G2:G5001, "NO") -> 0.16488515
E21: Etiquetas de columna | O21: Etiquetas de columna
E22: Asalariado | F22: Asegurado voluntario | G22: Convenios especiales de asegurados voluntarios | H22: Convenios especiales de trabajadores independientes | I22: Pensionados en su propio sistema | J22: Trabajador independiente | K22: Total general | O22: No | P22: Si | Q22: Total general
D23: Suma de % DE MOROSOSO | E23: 0.1198037 | F23: 0.13302752 | G23: 0 | H23: 0.025477707 | I23: 0 | J23: 0.56142857 | K23: 0.8397375 | N23: Suma de % DE MOROSOSO | O23: 0.16488515 | P23: 0.24046434 | Q23: 0.40534949

Sheet Gráficos morosidad numéricas
A1: Indicador de morosidad | B1: Promedio edad | E1: Etiquetas de columna | K1: Etiquetas de columna
A2: SI | B2: =AVERAGEIF(moras!H2:H5001, "SI", moras!P2:P5001) -> 43.635632 | E2: NO | F2: SI | G2: Total general | K2: NO | L2: SI | M2: Total general | O2: Opiniones:
A3: NO | B3: =AVERAGEIF(moras!H2:H5001, "NO", moras!P2:P5001) -> 41.542063 | D3: Suma de Promedio edad | E3: 41.542063 | F3: 43.635632 | G3: 85.177695 | J3: Suma de Promedio salario | K3: 690969.85 | L3: 498811.47 | M3: 1189781.3 | O3: Gráfico edad con morosidad: | P3: La diferencia entre la edad promedio entre los morosos y no morosos es de aproximadamente 2 años, por lo que no muestra relaciones consistentemente entre ellas, de igual manera las personas morosas presentan un promedio mayor que las no morosas, sin embargo al ser una diferencia tan pequeña lo único que se logra conlcuir es que la edad no está directamente relacionada a la morosidad.
A4: Indicador de morosidad | B4: Promedio salario | O4: Gráfico salario con morosidad: | P4: Primero se puede ver que el salario de los no morosos es un 38,52% mayor que el salario de las personas morosas, por lo que es una diferencia bastente grande entre ambos grupos. Entonces se puede notar el promedio de las personas que si son morosas es más bajo que el promedio de las personas que no son morosas, lo cual hace sentido pues personas con mayor ingreso tienen mayor capacidad de pago, lo cual lleva a menos morosidad, mientras que las las personas morosas tienen un ingreso menor, por lo cual son mas propensos a que no puedan pagar.
A5: SI | B5: =AVERAGEIF(moras!H2:H5001, "SI", moras!N2:N5001) -> 498811.47
A6: NO | B6: =AVERAGEIF(moras!H2:H5001, "NO", moras!N2:N5001) -> 690969.85
J19: Diferencia porcentual | K19: =(GETPIVOTDATA("Promedio salario",$J$1,"Indicador de morosidad","NO")-GETPIVOTDATA("Promedio salario",$J$1,"Indicador de morosidad","SI"))/GETPIVOTDATA("Promedio salario",$J$1,"Indicador de morosidad","SI") -> 0.38523248
